Workbook

Sheet MENU

Sheet KPI´S
B3: KPI´S
B6: 1.-Delivery time | H6: DELIVERY DAYS
B7: Delivery time expectations all the way to: | G7: Vancouver | H7: 6 | I7: 5 | J7: 7 | K7: 6 | L7: 7 | M7: 6 | N7: 5 | O7: 5 | P7: 5 | Q7: 6 | R7: 7 | S7: 7 | T7: 7
B8: VANCOUVER | C8: 7 DAYS
B9: TORONTO | C9: 6 DAYS | G9: Toronto | H9: 5 | I9: 6 | J9: 6 | K9: 6 | L9: 7 | M9: 8 | N9: 5 | O9: 6 | P9: 8 | Q9: 6 | R9: 5 | S9: 5 | T9: 5
O11: This indicator shows the avergae delivery time in days
L12: AVERAGE
L13: VAN | M13: =AVERAGE(H7:T7) -> 6.0769231 | O13: Makes it easy to find how many times deliveries are not on time
L14: TOR | M14: =AVERAGE(H9:T9) -> 6
O15: Show improving areas
B21: 2.- Trucks sold per month
G22: MONTH | H22: 1 | I22: 2 | J22: 3 | K22: 4 | L22: 5 | M22: 6 | N22: 7 | O22: 8 | P22: 9 | Q22: 10 | R22: 11 | S22: 12
B23: Target sales per month | G23: TRUCKS DELIVERED | H23: 6 | I23: 5 | J23: 6 | K23: 6 | L23: 7 | M23: 5 | N23: 6 | O23: 6 | P23: 5 | Q23: 4 | R23: 6 | S23: 6
B24: 6 TRUCKS
H26: AVERAGE
H27: =AVERAGE(H23:S23) -> 5.6666667 | I27: On average we are a little bit lower then our target
H29: This indicator show us periods of the year in which sales are lower
H31: We can find the way to control sales in the most flat way possible
H33: Makes visual where we failed and can tell us why with a deep analysis
B41: 3.- Percentage of waste
B43: Target of waste | G43: % WASTE PER MONTH | H43: 1 | I43: 2 | J43: 3 | K43: 4 | L43: 5 | M43: 6 | N43: 7 | O43: 8 | P43: 9 | Q43: 10 | R43: 11 | S43: 12
B44: MANGO | C44: =1-(1/1.8) -> 0.44444444 | G44: MANGO | H44: 0.4 | I44: 0.42 | J44: 0.44 | K44: 0.41 | L44: 0.47 | M44: 0.4 | N44: 0.46 | O44: 0.44 | P44: 0.42 | Q44: 0.41 | R44: 0.47 | S44: 0.44
B45: AVOCADO | C45: =1-(0.5/0.8) -> 0.375 | G45: AVOCADO | H45: 0.37 | I45: 0.35 | J45: 0.3 | K45: 0.38 | L45: 0.38 | M45: 0.39 | N45: 0.39 | O45: 0.38 | P45: 0.42 | Q45: 0.4 | R45: 0.37 | S45: 0.36
B46: SALAD | C46: 0.05 | G46: SALAD | H46: 0.04 | I46: 0.04 | J46: 0.02 | K46: 0.06 | L46: 0.05 | M46: 0.04 | N46: 0.05 | O46: 0.06 | P46: 0.07 | Q46: 0.03 | R46: 0.03 | S46: 0.05
B48: AVERAGE | Q48: This metric shows how much we waste when producing
B49: =AVERAGE(H44:S44) -> 0.43166667
B50: =AVERAGE(H45:S45) -> 0.37416667 | Q50: Each product has a waste tolerance, in the graph we can wee if it exceeds
B51: =AVERAGE(H46:S46) -> 0.045
Q52: This can tell us that we need to be more consistent with the waste, try to standarize the process
B61: 4.- Transportations cost per kg sold
B63: Transportation cost per kg | G63: COST | H63: 1 | I63: 2 | J63: 3 | K63: 4 | L63: 5 | M63: 6 | N63: 7 | O63: 8 | P63: 9 | Q63: 10 | R63: 11 | S63: 12
B64: AVOCADO | C64: ='COST ANALYSIS'!J18 -> 0.7 | G64: AVOCADO | H64: 0.7 | I64: 0.69 | J64: 0.67 | K64: 0.71 | L64: 0.78 | M64: 0.67 | N64: 0.65 | O64: 0.7 | P64: 0.68 | Q64: 0.7 | R64: 0.73 | S64: 0.72
B65: MANGO | C65: ='COST ANALYSIS'!J39 -> 1.75 | G65: MANGO | H65: 1.75 | I65: 1.72 | J65: 1.74 | K65: 1.77 | L65: 1.72 | M65: 1.78 | N65: 1.75 | O65: 1.75 | P65: 1.74 | Q65: 1.72 | R65: 1.78 | S65: 1.72
B66: SALAD | C66: ='COST ANALYSIS'!J62 -> 1.0666667 | G66: SALAD | H66: 1.08 | I66: 1.05 | J66: 1.11 | K66: 1.07 | L66: 1.06 | M66: 1.04 | N66: 1.09 | O66: 1.07 | P66: 1.07 | Q66: 1.07 | R66: 1.09 | S66: 1.06
Q67: Since transportation cost is variable, it is important to measure the cost per unit sold for each product
B69: AVERAGE | Q69: Reflects the volatility in freight costs
B70: AVOCADO | C70: =AVERAGE(H64:S64) -> 0.7
B71: MANGO | C71: =AVERAGE(H65:S65) -> 1.745 | Q71: Helps logistics to analyze the increases or decreases in freight prices to take decisions
B72: SALAD | C72: =AVERAGE(H66:S66) -> 1.0716667
B78: 5.- Inventory levels
...

Sheet P&L
D3: PROFIT AND LOSSES | L3: 100,000 avocado bags, 1 truck west, 1 truck east
J4: November 25 | L4: 40,000 mango bags, 1 trucks west, 1 trucks east
D5: TOTAL UNITS | E5: =SUM(E6:E8) -> 200000 | L5: 60,000 salad bags, 1 truck west, 1 truck east
D6: AVOCADO | E6: =50000*2 -> 100000
D7: MANGO | E7: 40000
D8: SALADS | E8: 60000
D10: SALES | F10: Unit Price | H10: TOTAL
E11: Avocado | F11: ='COST ANALYSIS'!J21 -> 9 | H11: =F11*E6 -> 900000
E12: Mango | F12: ='COST ANALYSIS'!J42 -> 12 | H12: =F12*E7 -> 480000
E13: Salads | F13: ='COST ANALYSIS'!J65 -> 2.5 | H13: =F13*E8 -> 150000
D15: TOTAL SALES | H15: =SUM(H11:H13) -> 1530000 | I15: Category ( COGS / OPEX)
D17: COGS | E17: Avocado | F17: ='COST ANALYSIS'!J20 -> 3.69 | H17: =F17*E6 -> 369000 | I17: COGS
E18: Mango | F18: ='COST ANALYSIS'!J41 -> 4.77 | H18: =F18*E7 -> 190800 | I18: COGS
E19: Salads | F19: ='COST ANALYSIS'!J64 -> 2.0074667 | H19: =F19*E8 -> 120448 | I19: COGS
D21: GROSS PROFIT | H21: =H15-H17-H18-H19 -> 849752 | I21: =H21/H15 -> 0.55539346
F22: PER UNIT
D23: Depreciation | F23: =H23/E5 -> 1.5 | H23: =6000000*0.05 -> 300000 | I23: OPEX
D24: Indirect Labor ( per unit ) | F24: =H24/$E$5 -> 0.325 | H24: =65000 -> 65000 | I24: OPEX
D25: Custom Broker Fee | F25: =H25/$E$5 -> 0.00525 | H25: =175*6 -> 1050 | I25: COGS | K25: 175 DLLS EACH TRUCK
D26: Taxation and Rights | F26: =H26/$E$5 -> 0 | H26: 0
D27: Import Freight | F27: =H27/$E$5 -> 0 | H27: 0
D28: Export Freight | F28: =H28/$E$5 -> 0 | H28: 0
D29: Handling | F29: =H29/$E$5 -> 0.0215 | H29: 4300 | I29: COGS
D30: Customs Warehouse | F30: =H30/$E$5 -> 0.0045 | H30: =150*6 -> 900 | I30: COGS
D31: Rent ( total units) per month | F31: =H31/$E$5 -> 0.015 | H31: 3000 | I31: OPEX
D32: Energy ( total units ) per month | F32: =H32/$E$5 -> 0.0075 | H32: 1500 | I32: OPEX
D33: Water ( total unit) per month | F33: =H33/$E$5 -> 0.002 | H33: 400 | I33: OPEX
D34: ERP License ( total unit) per month | F34: =H34/$E$5 -> 0.0015 | H34: 300 | I34: OPEX
D35: Insurance | F35: =H35/$E$5 -> 0.009 | H35: =300*6 -> 1800
D36: TOTAL COGS AND OPEX | H36: =SUM(H23:H35) -> 378250
D37: EBIT | H37: =H21-H36 -> 471502 | I37: =H37/H15 -> 0.30817124
D38: TAX | H38: =H37*0.3 -> 141450.6
D39: NET PROFIT | H39: =H37-H38 -> 330051.4 | I39: =H39/H15 -> 0.21571987
D43: TOTAL UNIT COST
D44: TOTAL FIXED COST PER UNIT | E44: =SUM(F23:F35) -> 1.89125
D45: TOTAL COST PER UNIT AVOCADO | E45: =$E$44+F17 -> 5.58125
D46: TOTAL COST PER UNIT MANGO | E46: =$E$44+F18 -> 6.66125
D47: TOTAL COST PER UNIT SALAD | E47: =$E$44+F19 -> 3.8987167 | F47: Salad is not a great product, after adding the fixed cost, our cost is higher than our selling price

Sheet COST ANALYSIS
D3: AVOCADO
D4: Each bag of 500 grams | L4: IMPACT, INCREASE IN FREIGH PRICE 20%
H5: Price per | I5: Quantity required | J5: Total | L5: =J18*0.2 -> 0.14
D6: Raw materials: | H6: KG | J6: USD
D7: Fresh avocado (KG) | H7: 2.2 | I7: 0.8 | J7: =H7*I7 -> 1.76
D9: Packaging: | H9: UNIT
D10: Vacuum bag 20X15 cm | H10: 0.12 | I10: 1 | J10: =I10*H10 -> 0.12
D11: Secundary packaging (for 20 bags) | H11: 1.8 | I11: 0.05 | J11: =I11*H11 -> 0.09
D13: Pasteurization, freezing, etc. | H13: 0.5 | I13: 1 | J13: =I13*H13 -> 0.5
D14: Quality verifications | H14: 0.1 | I14: 1 | J14: =I14*H14 -> 0.1
D15: Cooling and warehousing | H15: 0.42 | I15: 1 | J15: =I15*H15 -> 0.42
D16: Total production cost per unit | J16: =SUM(J7:J15) -> 2.99
H17: TRUCK
D18: Transportation | H18: 35000 | I18: =1/50000 -> 2e-05 | J18: =I18*H18 -> 0.7 | K18: *Since there are 50,000 pieces by truck
D20: Final cost per unit | J20: =J16+J18 -> 3.69
I21: Selling price | J21: 9
I22: Maring | J22: =(J21/J20)-1 -> 1.4390244
D24: MANGO CUBES
D25: Each bag of 1KG grams | L25: IMPACT, INCREASE IN FREIGH PRICE 20%
H26: Price per | I26: Quantity required | J26: Total | L26: =J39*0.2 -> 0.35
D27: Raw materials: | H27: KG | J27: USD
D28: Fresh mango (KG) | H28: 0.9 | I28: 1.8 | J28: =H28*I28 -> 1.62
D30: Packaging: | H30: UNIT
D31: Vacuum bag 25X20 cm | H31: 0.16 | I31: 1 | J31: =I31*H31 -> 0.16
D32: Secundary packaging (for 10 bags) | H32: 1.6 | I32: 0.1 | J32: =I32*H32 -> 0.16
D34: Industrial processing | H34: 0.5 | I34: 1 | J34: =I34*H34 -> 0.5
D35: Quality verifications | H35: 0.12 | I35: 1 | J35: =I35*H35 -> 0.12
D36: Cooling and warehousing | H36: 0.46 | I36: 1 | J36: =I36*H36 -> 0.46
D37: Total production cost per unit | J37: =SUM(J28:J36) -> 3.02
H38: TRUCK
D39: Transportation | H39: 35000 | I39: =1/20000 -> 5e-05 | J39: =I39*H39 -> 1.75 | K39: *Since there are 20,000 pieces per truck
D41: Final cost per unit | J41: =J37+J39 -> 4.77
I42: Selling price | J42: 12
I43: Maring | J43: =(J42/J41)-1 -> 1.5157233
D45: SALADS
D46: Each bag of 250 grams | L46: IMPACT, INCREASE IN FREIGH PRICE 20%
H47: Price per | I47: Quantity required | J47: Total | L47: =J62*0.2 -> 0.21333333
D48: Raw materials: | H48: KG | J48: USD
D49: Fresh lettuces mix (KG) | H49: 0.9 | I49: 0.112 | J49: =H49*I49 -> 0.1008
D50: Tomato | H50: 1.2 | I50: 0.05 | J50: =H50*I50 -> 0.06
...

Sheet IMPACT ANALYSIS
D3: PROFIT AND LOSSES | L3: 100,000 avocado bags, 1 truck west, 1 truck east
J4: November 25 | L4: 40,000 mango bags, 1 trucks west, 1 trucks east
D5: TOTAL UNITS | E5: =SUM(E6:E8) -> 200000 | L5: 60,000 salad bags, 1 truck west, 1 truck east
D6: AVOCADO | E6: =50000*2 -> 100000
D7: MANGO | E7: 40000
D8: SALADS | E8: 60000
L9: 5 IMPACTS
D10: SALES | F10: Unit Price | H10: TOTAL | L10: 1.- INCREASE OF 20% IN THE FREIGHT FOR ALL THE PRODUCTS
E11: Avocado | F11: ='COST ANALYSIS'!J21 -> 9 | H11: =F11*E6 -> 900000 | L11: 2.- DOUBLE AMOUNT INVESTED IN EQUIPMENT, RESULTING IN DOUBLE DEPRECIATION
E12: Mango | F12: ='COST ANALYSIS'!J42 -> 12 | H12: =F12*E7 -> 480000 | L12: 3.- INCREASE IN 30% IN INDIRECT LABOR
E13: Salads | F13: ='COST ANALYSIS'!J65 -> 2.5 | H13: =F13*E8 -> 150000 | L13: 4.- INCREASE IN 20% IN INSURANCE
L14: 5.- PAYING HIGHER RENT BY 10%
D15: TOTAL SALES | H15: =SUM(H11:H13) -> 1530000 | I15: Category ( COGS / OPEX)
D17: COGS | E17: Avocado | F17: ='COST ANALYSIS'!J20+'COST ANALYSIS'!L5 -> 3.83 | H17: =F17*E6 -> 383000 | I17: COGS | L17: RESULTS
E18: Mango | F18: ='COST ANALYSIS'!J41+'COST ANALYSIS'!L26 -> 5.12 | H18: =F18*E7 -> 204800 | I18: COGS | L18: Profit margin would drop to 5% if all of these 5 effect happened
E19: Salads | F19: ='COST ANALYSIS'!J64+'COST ANALYSIS'!L47 -> 2.2208 | H19: =F19*E8 -> 133248 | I19: COGS | L19: Something we conclude is the high impact freights have in our price, meaning that it is an area in which we can focus in bargaining to maximize profits
D21: GROSS PROFIT | H21: =H15-H17-H18-H19 -> 808952 | I21: =H21/H15 -> 0.5287268
F22: PER UNIT
D23: Depreciation | F23: =H23/E5 -> 3 | H23: =12000000*0.05 -> 600000 | I23: OPEX
D24: Indirect Labor ( per unit ) | F24: =H24/$E$5 -> 0.4225 | H24: =65000*1.3 -> 84500 | I24: OPEX
D25: Custom Broker Fee | F25: =H25/$E$5 -> 0.00525 | H25: =175*6 -> 1050 | I25: COGS | K25: 175 DLLS EACH TRUCK
D26: Taxation and Rights | F26: =H26/$E$5 -> 0 | H26: 0
D27: Import Freight | F27: =H27/$E$5 -> 0 | H27: 0
D28: Export Freight | F28: =H28/$E$5 -> 0 | H28: 0
D29: Handling | F29: =H29/$E$5 -> 0.0215 | H29: 4300 | I29: COGS
D30: Customs Warehouse | F30: =H30/$E$5 -> 0.0045 | H30: =150*6 -> 900 | I30: COGS
D31: Rent ( total units) per month | F31: =H31/$E$5 -> 0.0165 | H31: =3000*1.1 -> 3300 | I31: OPEX
D32: Energy ( total units ) per month | F32: =H32/$E$5 -> 0.0075 | H32: 1500 | I32: OPEX
D33: Water ( total unit) per month | F33: =H33/$E$5 -> 0.002 | H33: 400 | I33: OPEX
D34: ERP License ( total unit) per month | F34: =H34/$E$5 -> 0.0015 | H34: 300 | I34: OPEX
D35: Insurance | F35: =H35/$E$5 -> 0.0108 | H35: =300*6*1.2 -> 2160
D36: TOTAL COGS AND OPEX | H36: =SUM(H23:H35) -> 698410
D37: EBIT | H37: =H21-H36 -> 110542 | I37: =H37/H15 -> 0.072249673
D38: TAX | H38: =H37*0.3 -> 33162.6
D39: NET PROFIT | H39: =H37-H38 -> 77379.4 | I39: =H39/H15 -> 0.050574771
D43: TOTAL UNIT COST
D44: TOTAL FIXED COST PER UNIT | E44: =SUM(F23:F35) -> 3.49205
D45: TOTAL COST PER UNIT AVOCADO | E45: =$E$44+F17 -> 7.32205
D46: TOTAL COST PER UNIT MANGO | E46: =$E$44+F18 -> 8.61205
D47: TOTAL COST PER UNIT SALAD | E47: =$E$44+F19 -> 5.71285 | F47: Salad is not a great product, after adding the fixed cost, our cost is higher than our selling price

Sheet CUBIC MEASURE
E3: AVOCADO | J3: MANGO CUBES | O3: SALADS
D4: DIMENTION CALCULATIONS | I4: DIMENTION CALCULATIONS | N4: DIMENTION CALCULATIONS
D6: TRUCK CAPACITY | F6: 25000 | G6: KG | I6: TRUCK CAPACITY | K6: 25000 | L6: KG | N6: TRUCK CAPACITY | P6: 25000 | Q6: KG
D7: BOX WEIGHT (20 BAGS) | F7: 10 | G7: KG | I7: BOX WEIGHT (10 BAGS) | K7: =1*10 -> 10 | L7: KG | N7: BOX WEIGHT (20 BAGS) | P7: =20*0.25 -> 5 | Q7: KG
D8: BOX PER TRUCK | F8: =F6/F7 -> 2500 | I8: BOX PER TRUCK | K8: 2000 | L8: M^3 LIMITED | N8: BOX PER TRUCK | P8: 1500 | Q8: M^3 LIMITED
D10: BOX DIMENTION | E10: 40*25*20 cm | F10: =0.4*0.25*0.2 -> 0.02 | G10: M^3 | I10: BOX DIMENTION | J10: 45*30*25 cm | K10: =0.45*0.3*0.25 -> 0.03375 | L10: M^3 | N10: BOX DIMENTION | O10: 40*40*30 cm | P10: =0.4*0.4*0.3 -> 0.048 | Q10: M^3
D11: TOTAL BOX DIMENTION | F11: =F10*F8 -> 50 | G11: M^3 | I11: TOTAL BOX DIMENTION | K11: =K10*K8 -> 67.5 | L11: M^3 | N11: TOTAL BOX DIMENTION | P11: =P10*P8 -> 72 | Q11: M^3
D12: TRUCK CUBIC CAPACITY | F12: 90 | G12: M^3 | I12: TRUCK CUBIC CAPACITY | K12: 90 | L12: M^3 | N12: TRUCK CUBIC CAPACITY | P12: 90 | Q12: M^3
D13: ROOM LEFT | F13: =F12-F11 -> 40 | G13: M^3 | I13: ROOM LEFT | K13: =K12-K11 -> 22.5 | L13: M^3 | N13: ROOM LEFT | P13: =P12-P11 -> 18 | Q13: M^3
D15: ACHIEVABLE!! | I15: ACHIEVABLE!! | N15: ACHIEVABLE!!
D16: Total unit per truck | F16: =F8*20 -> 50000 | I16: Total unit per truck | K16: =K8*10 -> 20000 | N16: Total unit per truck | P16: =P8*20 -> 30000
D18: REFERENCES | P18: =0.25*30000 -> 7500
D19: Secretaría de Comunicaciones y Transportes (SCT). (2018, 26 de diciembre). NORMA Oficial Mexicana NOM-012-SCT-2-2017, Sobre el peso y dimensiones máximas con los que pueden circular los vehículos de autotransporte que transitan en las vías generales de comunicación de jurisdicción federal. Diario Oficial de la Federación. https://www.dof.gob.mx/normasOficiales/6890/sct5a12_C/sct5a12_C.html
D25: Federal Highway Administration (FHWA). (2000, 18 de agosto). Federal Size Regulations for Commercial Motor Vehicles. U.S. Department of Transportation. https://ops.fhwa.dot.gov/freight/publications/size_regs_final_rpt/
