Workbook

Sheet WAREHOUSES
B3: WAREHOUSES
C7: WAREHOUSE'S SUPPLY LINE
C8: SCENARIO NO.1
C9: Consolidation Centers | F9: Destination Centers
C10: Guadalajara | F10: San Diego, CA
C11: Uruapan | F11: Los Angeles, CA
C12: Monterrey | F12: San Francisco, CA
C13: Hermosillo | F13: Portland, OR
C14: Laredo, Texas | F14: Seattle, WA
F15: Vancouver, Canada
C16: SCENARIO NO.2
C17: Consolidation Centers | F17: Destination Centers
C18: Guadalajara | F18: Phoenix, AZ
C19: Uruapan | F19: Dallas, TX
C20: Monterrey | F20: Chicago, IL
C21: Hermosillo | F21: Atlanta, GA
C22: Laredo, Texas | F22: Nueva York, NY
F23: Toronto, Canadá

Sheet TRANSPORTATION COST 
E4: DISTRIBUTION & CONSOLIDTION CENTERS DISTANCES (KM)
E5: SCENARIO NO.1
E6: Origen / Destino | F6: San Diego, CA | G6: Los Ángeles, CA | H6: San Francisco, CA | I6: Portland, OR | J6: Seattle, WA | K6: Vancouver, CAN
E7: Guadalajara, JA | F7: 2250 | G7: 2380 | H7: 2780 | I7: 3320 | J7: 3650 | K7: 3880
E8: Uruapan, MI | F8: 2180 | G8: 2310 | H8: 2710 | I8: 3250 | J8: 3580 | K8: 3810
E9: Monterrey, NL | F9: 1650 | G9: 1780 | H9: 2180 | I9: 2720 | J9: 3050 | K9: 3280
E10: Hermosillo, SN | F10: 850 | G10: 980 | H10: 1380 | I10: 1920 | J10: 2250 | K10: 2480
E11: Laredo, TX | F11: 1550 | G11: 1680 | H11: 2080 | I11: 2620 | J11: 2950 | K11: 3180
E12: SCENARIO NO.2
E13: Origen / Destino | F13: Phoenix, AZ | G13: Dallas, TX | H13: Chicago, IL | I13: Atlanta, GA | J13: Nueva York, NY | K13: Toronto, CAN
E14: Guadalajara, JA | F14: 1980 | G14: 1760 | H14: 2980 | I14: 3220 | J14: 4050 | K14: 3540
E15: Uruapan, MI | F15: 1910 | G15: 1690 | H15: 2910 | I15: 3150 | J15: 3980 | K15: 3470
E16: Monterrey, NL | F16: 1380 | G16: 1160 | H16: 2380 | I16: 2620 | J16: 3450 | K16: 2940
E17: Hermosillo, SN | F17: 580 | G17: 1450 | H17: 2670 | I17: 2910 | J17: 3740 | K17: 3230
E18: Laredo, TX | F18: 1280 | G18: 640 | H18: 1860 | I18: 2100 | J18: 2930 | K18: 2420
E21: USD COST PER KM IN AVOCADO ROUTE
E22: Trucking Cost: | H22: 35000
E23: SCENARIO NO.1
E24: Origen / Destino | F24: San Diego, CA | G24: Los Ángeles, CA | H24: San Francisco, CA | I24: Portland, OR | J24: Seattle, WA | K24: Vancouver, CAN
E25: Guadalajara, JA | F25: =$H$22/F7 -> 15.555556 | G25: =$H$22/G7 -> 14.705882 | H25: =$H$22/H7 -> 12.589928 | I25: =$H$22/I7 -> 10.542169 | J25: =$H$22/J7 -> 9.5890411 | K25: =$H$22/K7 -> 9.0206186
E26: Uruapan, MI | F26: =$H$22/F8 -> 16.055046 | G26: =$H$22/G8 -> 15.151515 | H26: =$H$22/H8 -> 12.915129 | I26: =$H$22/I8 -> 10.769231 | J26: =$H$22/J8 -> 9.7765363 | K26: =$H$22/K8 -> 9.1863517
E27: Monterrey, NL | F27: =$H$22/F9 -> 21.212121 | G27: =$H$22/G9 -> 19.662921 | H27: =$H$22/H9 -> 16.055046 | I27: =$H$22/I9 -> 12.867647 | J27: =$H$22/J9 -> 11.47541 | K27: =$H$22/K9 -> 10.670732
E28: Hermosillo, SN | F28: =$H$22/F10 -> 41.176471 | G28: =$H$22/G10 -> 35.714286 | H28: =$H$22/H10 -> 25.362319 | I28: =$H$22/I10 -> 18.229167 | J28: =$H$22/J10 -> 15.555556 | K28: =$H$22/K10 -> 14.112903
E29: Laredo, TX | F29: =$H$22/F11 -> 22.580645 | G29: =$H$22/G11 -> 20.833333 | H29: =$H$22/H11 -> 16.826923 | I29: =$H$22/I11 -> 13.358779 | J29: =$H$22/J11 -> 11.864407 | K29: =$H$22/K11 -> 11.006289
E30: SCENARIO NO.2
E31: Origen / Destino | F31: Phoenix, AZ | G31: Dallas, TX | H31: Chicago, IL | I31: Atlanta, GA | J31: Nueva York, NY | K31: Toronto, CAN
E32: Guadalajara, JA | F32: =$H$22/F14 -> 17.676768 | G32: =$H$22/G14 -> 19.886364 | H32: =$H$22/H14 -> 11.744966 | I32: =$H$22/I14 -> 10.869565 | J32: =$H$22/J14 -> 8.6419753 | K32: =$H$22/K14 -> 9.8870056
E33: Uruapan, MI | F33: =$H$22/F15 -> 18.324607 | G33: =$H$22/G15 -> 20.710059 | H33: =$H$22/H15 -> 12.027491 | I33: =$H$22/I15 -> 11.111111 | J33: =$H$22/J15 -> 8.7939698 | K33: =$H$22/K15 -> 10.086455
E34: Monterrey, NL | F34: =$H$22/F16 -> 25.362319 | G34: =$H$22/G16 -> 30.172414 | H34: =$H$22/H16 -> 14.705882 | I34: =$H$22/I16 -> 13.358779 | J34: =$H$22/J16 -> 10.144928 | K34: =$H$22/K16 -> 11.904762
E35: Hermosillo, SN | F35: =$H$22/F17 -> 60.344828 | G35: =$H$22/G17 -> 24.137931 | H35: =$H$22/H17 -> 13.108614 | I35: =$H$22/I17 -> 12.027491 | J35: =$H$22/J17 -> 9.3582888 | K35: =$H$22/K17 -> 10.835913
E36: Laredo, TX | F36: =$H$22/F18 -> 27.34375 | G36: =$H$22/G18 -> 54.6875 | H36: =$H$22/H18 -> 18.817204 | I36: =$H$22/I18 -> 16.666667 | J36: =$H$22/J18 -> 11.945392 | K36: =$H$22/K18 -> 14.46281
E39: USD COST PER KM IN MANGO ROUTE
E40: Trucking Cost: | H40: 35000
E41: SCENARIO NO.1
E42: Origen / Destino | F42: San Diego, CA | G42: Los Ángeles, CA | H42: San Francisco, CA | I42: Portland, OR | J42: Seattle, WA | K42: Vancouver, CAN
E43: Guadalajara, JA | F43: =$H$40/F7 -> 15.555556 | G43: =$H$40/G7 -> 14.705882 | H43: =$H$40/H7 -> 12.589928 | I43: =$H$40/I7 -> 10.542169 | J43: =$H$40/J7 -> 9.5890411 | K43: =$H$40/K7 -> 9.0206186
E44: Uruapan, MI | F44: =$H$40/F8 -> 16.055046 | G44: =$H$40/G8 -> 15.151515 | H44: =$H$40/H8 -> 12.915129 | I44: =$H$40/I8 -> 10.769231 | J44: =$H$40/J8 -> 9.7765363 | K44: =$H$40/K8 -> 9.1863517
E45: Monterrey, NL | F45: =$H$40/F9 -> 21.212121 | G45: =$H$40/G9 -> 19.662921 | H45: =$H$40/H9 -> 16.055046 | I45: =$H$40/I9 -> 12.867647 | J45: =$H$40/J9 -> 11.47541 | K45: =$H$40/K9 -> 10.670732
E46: Hermosillo, SN | F46: =$H$40/F10 -> 41.176471 | G46: =$H$40/G10 -> 35.714286 | H46: =$H$40/H10 -> 25.362319 | I46: =$H$40/I10 -> 18.229167 | J46: =$H$40/J10 -> 15.555556 | K46: =$H$40/K10 -> 14.112903
E47: Laredo, TX | F47: =$H$40/F11 -> 22.580645 | G47: =$H$40/G11 -> 20.833333 | H47: =$H$40/H11 -> 16.826923 | I47: =$H$40/I11 -> 13.358779 | J47: =$H$40/J11 -> 11.864407 | K47: =$H$40/K11 -> 11.006289
...

Sheet SUPPLY & DEMAND
F2: S U P P L Y | O2: D E M A N D
F4: Objetivo: Satisfacer el 2% de la demanda total de cada mercado.
F5: Consolidation Centers | M5: Destination Centers
F6: TOTAL AVOCADO DEMAND : | K6: =Q21 -> 2416303.3 | M6: AVOCADO
F7: Consolidation Centers | I7: CAPACITY | J7: TOTAL UNIT SUPPLY | M7: TOTAL AVOCADO DEMAND USA | N7: 333000000 | O7: Consumption Percentage per City | P7: Estimated Avocado consumption | Q7: 2% of the Estimated Demand
F8: Guadalajara | I8: 0.2 | J8: =$K$6*I8 -> 483260.67 | M8: San Diego, CA | O8: 0.013 | P8: =O8*$N$7 -> 4329000 | Q8: =P8*0.02 -> 86580
F9: Uruapan | I9: 0.4 | J9: =$K$6*I9 -> 966521.33 | M9: Los Angeles, CA | O9: 0.065 | P9: =O9*$N$7 -> 21645000 | Q9: =P9*0.02 -> 432900
F10: Monterrey | I10: 0.15 | J10: =$K$6*I10 -> 362445.5 | M10: San Francisco, CA | O10: 0.022 | P10: =O10*$N$7 -> 7326000 | Q10: =P10*0.02 -> 146520
F11: Hermosillo | I11: 0.15 | J11: =$K$6*I11 -> 362445.5 | M11: Portland, OR | O11: 0.007 | P11: =O11*$N$7 -> 2331000 | Q11: =P11*0.02 -> 46620
F12: Laredo, Texas | I12: 0.1 | J12: =$K$6*I12 -> 241630.33 | M12: Seattle, WA | O12: 0.015 | P12: =O12*$N$7 -> 4995000 | Q12: =P12*0.02 -> 99900
F13: TOTAL SUPPLY | I13: =SUM(I8:I12) -> 1 | J13: =SUM(J8:K12) -> 2416303.3 | M13: Phoenix, AZ | O13: 0.02 | P13: =O13*$N$7 -> 6660000 | Q13: =P13*0.02 -> 133200
F14: TOTAL MANGO DEMAND : | K14: =Q40 -> 1313290 | M14: Dallas, TX | O14: 0.035 | P14: =O14*$N$7 -> 11655000 | Q14: =P14*0.02 -> 233100
F15: Consolidation Centers | I15: CAPACITY | J15: TOTAL UNIT SUPPLY | M15: Chicago, IL | O15: 0.05 | P15: =O15*$N$7 -> 16650000 | Q15: =P15*0.02 -> 333000
F16: Guadalajara (Jalisco) | I16: 0.25 | J16: =$K$14*I16 -> 328322.5 | M16: Atlanta, GA | O16: 0.03 | P16: =O16*$N$7 -> 9990000 | Q16: =P16*0.02 -> 199800
F17: Uruapan (Michoacán) - Main avocado producer | I17: 0.35 | J17: =$K$14*I17 -> 459651.5 | M17: Nueva York, NY | O17: 0.075 | P17: =O17*$N$7 -> 24975000 | Q17: =P17*0.02 -> 499500
F18: Monterrey (Nuevo León) - Logistics hub | I18: 0.15 | J18: =$K$14*I18 -> 196993.5 | M18: TOTAL AVOCADO DEMAND CANADA | N18: 26305556 | O18: Consumption Percentage per City | P18: Estimated Avocado consumption | Q18: 2% of the Estimated Demand
F19: Hermosillo (Sonora) | I19: 0.15 | J19: =$K$14*I19 -> 196993.5 | M19: Toronto, Canadá | O19: 0.28 | P19: =$N$18*O19 -> 7365555.7 | Q19: =P19*0.02 -> 147311.11
F20: Laredo, Texas (As a redistribution center/secondary origin) | I20: 0.1 | J20: =$K$14*I20 -> 131329 | M20: Vancouver, Canada | O20: 0.11 | P20: =$N$18*O20 -> 2893611.2 | Q20: =P20*0.02 -> 57872.223
F21: TOTAL SUPPLY | I21: =SUM(I16:I20) -> 1 | J21: =SUM(J16:K20) -> 1313290 | M21: OUR TOTAL AVOCADO DEMAND | Q21: =SUM(Q8:Q20) -> 2416303.3
F22: TOTAL SALAD DEMAND | K22: =Q58 -> 3187920
F23: Consolidation Centers | I23: CAPACITY | J23: TOTAL UNIT SUPPLY
F24: Guadalajara (Jalisco) | I24: 0.2 | J24: =$K$22*I24 -> 637584 | M24: Destination Centers
F25: Uruapan (Michoacán) - Main avocado producer | I25: 0.4 | J25: =$K$22*I25 -> 1275168 | M25: MANGOES
F26: Monterrey (Nuevo León) - Logistics hub | I26: 0.15 | J26: =$K$22*I26 -> 478188 | M26: TOTAL MANGO DEMAND USA | N26: 116700000 | O26: Consumption Percentage per City | P26: Estimated Avocado consumption | Q26: 2% of the Estimated Demand
F27: Hermosillo (Sonora) | I27: 0.15 | J27: =$K$22*I27 -> 478188 | M27: San Diego, CA | O27: 0.02 | P27: =O27*$N$26 -> 2334000 | Q27: =P27*0.02 -> 46680
F28: Laredo, Texas (As a redistribution center/secondary origin) | I28: 0.1 | J28: =$K$22*I28 -> 318792 | M28: Los Angeles, CA | O28: 0.12 | P28: =O28*$N$26 -> 14004000 | Q28: =P28*0.02 -> 280080
F29: TOTAL SUPPLY | I29: =SUM(I24:I28) -> 1 | J29: =SUM(J24:K28) -> 3187920 | M29: San Francisco, CA | O29: 0.04 | P29: =O29*$N$26 -> 4668000 | Q29: =P29*0.02 -> 93360
M30: Portland, OR | O30: 0.015 | P30: =O30*$N$26 -> 1750500 | Q30: =P30*0.02 -> 35010
M31: Seattle, WA | O31: 0.02 | P31: =O31*$N$26 -> 2334000 | Q31: =P31*0.02 -> 46680
M32: Phoenix, AZ | O32: 0.03 | P32: =O32*$N$26 -> 3501000 | Q32: =P32*0.02 -> 70020
M33: Dallas, TX | O33: 0.04 | P33: =O33*$N$26 -> 4668000 | Q33: =P33*0.02 -> 93360
F34: REFERENCES | M34: Chicago, IL | O34: 0.07 | P34: =O34*$N$26 -> 8169000 | Q34: =P34*0.02 -> 163380
M35: Atlanta, GA | O35: 0.03 | P35: =O35*$N$26 -> 3501000 | Q35: =P35*0.02 -> 70020
F36: https://edis.ifas.ufl.edu/publication/FE1150 | M36: Nueva York, NY | O36: 0.1 | P36: =O36*$N$26 -> 11670000 | Q36: =P36*0.02 -> 233400
M37: TOTAL AVOCADO DEMAND CANADA | N37: 25900000 | O37: Consumption Percentage per City | P37: Estimated Avocado consumption | Q37: 2% of the Estimated Demand
F38: https://worldpopulationreview.com/country-rankings/avocado-consumption-by-country | M38: Toronto, Canadá | O38: 0.23 | P38: =N37*O38 -> 5957000 | Q38: =P38*0.02 -> 119140
M39: Vancouver, Canada | O39: 0.12 | P39: =O39*N37 -> 3108000 | Q39: =P39*0.02 -> 62160
F40: https://www.thepacker.com/news/produce-crops/heres-how-much-us-imports-and-consumption-mangoes-has-changed-over-time | M40: OUR TOTAL MANGO DEMAND | Q40: =SUM(Q27:Q39) -> 1313290
M42: Destination Centers
M43: SALAD
...

Sheet NORTHWEST CORNER
D3: NORTHWEST CORNER
D4: SCENARIO NO.1 AVOCADO
D5: Origen / Destino | E5: San Diego, CA | G5: Los Ángeles, CA | I5: San Francisco, CA | K5: Portland, OR | M5: Seattle, WA | O5: Vancouver, CAN | Q5: Phoenix, AZ | R5: Dallas, TX | S5: Dallas, TX | T5: Atlanta, GA | U5: Chicago, IL | V5: Atlanta, GA | W5: Atlanta, GA | X5: Dallas, TX | Y5: Nueva York, NY | Z5: Toronto, CAN | AA5: Toronto, CAN | AC5: SUPPLY
D6: Guadalajara, JA | E6: =E11 -> 86580 | F6: ='TRANSPORTATION COST '!F25 -> 15.555556 | G6: =AE6 -> 396680.67 | H6: ='TRANSPORTATION COST '!G25 -> 14.705882 | J6: ='TRANSPORTATION COST '!H25 -> 12.589928 | L6: ='TRANSPORTATION COST '!I25 -> 10.542169 | N6: ='TRANSPORTATION COST '!J25 -> 9.5890411 | P6: ='TRANSPORTATION COST '!K25 -> 9.0206186 | R6: ='TRANSPORTATION COST '!F32 -> 17.676768 | T6: ='TRANSPORTATION COST '!G32 -> 19.886364 | V6: ='TRANSPORTATION COST '!H32 -> 11.744966 | X6: ='TRANSPORTATION COST '!I32 -> 10.869565 | Z6: ='TRANSPORTATION COST '!J32 -> 8.6419753 | AB6: ='TRANSPORTATION COST '!K32 -> 9.8870056 | AC6: {='SUPPLY & DEMAND'!J8:K8} -> 483260.67 | AD6: 0 | AE6: =AC6-E6 -> 396680.67 | AF6: =AE6-G6 -> 0
D7: Uruapan, MI | F7: ='TRANSPORTATION COST '!F26 -> 16.055046 | G7: =G12 -> 36219.333 | H7: ='TRANSPORTATION COST '!G26 -> 15.151515 | I7: =I11 -> 146520 | J7: ='TRANSPORTATION COST '!H26 -> 12.915129 | K7: =K11 -> 46620 | L7: ='TRANSPORTATION COST '!I26 -> 10.769231 | M7: =M11 -> 99900 | N7: ='TRANSPORTATION COST '!J26 -> 9.7765363 | O7: =O11 -> 57872.223 | P7: ='TRANSPORTATION COST '!K26 -> 9.1863517 | Q7: =Q11 -> 133200 | R7: ='TRANSPORTATION COST '!F33 -> 18.324607 | S7: =S11 -> 233100 | T7: ='TRANSPORTATION COST '!G33 -> 20.710059 | U7: =AK7 -> 213089.78 | V7: ='TRANSPORTATION COST '!H33 -> 12.027491 | X7: ='TRANSPORTATION COST '!I33 -> 11.111111 | Z7: ='TRANSPORTATION COST '!J33 -> 8.7939698 | AB7: ='TRANSPORTATION COST '!K33 -> 10.086455 | AC7: {='SUPPLY & DEMAND'!J9:K9} -> 966521.33 | AD7: 0 | AE7: =AC7-G7 -> 930302 | AF7: =AE7-I7 -> 783782 | AG7: =AF7-K7 -> 737162 | AH7: =AG7-M7 -> 637262 | AI7: =AH7-O7 -> 579389.78 | AJ7: =AI7-Q7 -> 446189.78 | AK7: =AJ7-S7 -> 213089.78 | AL7: =AK7-U7 -> 0
D8: Monterrey, NL | F8: ='TRANSPORTATION COST '!F27 -> 21.212121 | H8: ='TRANSPORTATION COST '!G27 -> 19.662921 | J8: ='TRANSPORTATION COST '!H27 -> 16.055046 | L8: ='TRANSPORTATION COST '!I27 -> 12.867647 | N8: ='TRANSPORTATION COST '!J27 -> 11.47541 | P8: ='TRANSPORTATION COST '!K27 -> 10.670732 | R8: ='TRANSPORTATION COST '!F34 -> 25.362319 | T8: ='TRANSPORTATION COST '!G34 -> 30.172414 | U8: =U12 -> 119910.22 | V8: ='TRANSPORTATION COST '!H34 -> 14.705882 | W8: =W11 -> 199800 | X8: ='TRANSPORTATION COST '!I34 -> 13.358779 | Y8: =AF8 -> 42735.279 | Z8: ='TRANSPORTATION COST '!J34 -> 10.144928 | AB8: ='TRANSPORTATION COST '!K34 -> 11.904762 | AC8: {='SUPPLY & DEMAND'!J10:K10} -> 362445.5 | AD8: 0 | AE8: =AC8-U8 -> 242535.28 | AF8: =AE8-W8 -> 42735.279 | AG8: =AF8-Y8 -> 0
D9: Hermosillo, SN | F9: ='TRANSPORTATION COST '!F28 -> 41.176471 | H9: ='TRANSPORTATION COST '!G28 -> 35.714286 | J9: ='TRANSPORTATION COST '!H28 -> 25.362319 | L9: ='TRANSPORTATION COST '!I28 -> 18.229167 | N9: ='TRANSPORTATION COST '!J28 -> 15.555556 | P9: ='TRANSPORTATION COST '!K28 -> 14.112903 | R9: ='TRANSPORTATION COST '!F35 -> 60.344828 | T9: ='TRANSPORTATION COST '!G35 -> 24.137931 | V9: ='TRANSPORTATION COST '!H35 -> 13.108614 | X9: ='TRANSPORTATION COST '!I35 -> 12.027491 | Y9: =AC9 -> 362445.5 | Z9: ='TRANSPORTATION COST '!J35 -> 9.3582888 | AB9: ='TRANSPORTATION COST '!K35 -> 10.835913 | AC9: {='SUPPLY & DEMAND'!J11:K11} -> 362445.5 | AD9: 0 | AE9: =AC9-Y9 -> 0
D10: Laredo, TX | F10: ='TRANSPORTATION COST '!F29 -> 22.580645 | H10: ='TRANSPORTATION COST '!G29 -> 20.833333 | J10: ='TRANSPORTATION COST '!H29 -> 16.826923 | L10: ='TRANSPORTATION COST '!I29 -> 13.358779 | N10: ='TRANSPORTATION COST '!J29 -> 11.864407 | P10: ='TRANSPORTATION COST '!K29 -> 11.006289 | R10: ='TRANSPORTATION COST '!F36 -> 27.34375 | T10: ='TRANSPORTATION COST '!G36 -> 54.6875 | V10: ='TRANSPORTATION COST '!H36 -> 18.817204 | X10: ='TRANSPORTATION COST '!I36 -> 16.666667 | Y10: =Y13 -> 94319.22 | Z10: ='TRANSPORTATION COST '!J36 -> 11.945392 | AA10: =AA11 -> 147311.11 | AB10: ='TRANSPORTATION COST '!K36 -> 14.46281 | AC10: {='SUPPLY & DEMAND'!J12:K12} -> 241630.33 | AD10: 0 | AE10: =AC10-Y10 -> 147311.11 | AF10: =AE10-AA10 -> -3.2014214e-10
D11: DEMAND | E11: ='SUPPLY & DEMAND'!Q8 -> 86580 | F11: =E11-E6 -> 0 | G11: ='SUPPLY & DEMAND'!Q9 -> 432900 | I11: ='SUPPLY & DEMAND'!Q10 -> 146520 | K11: ='SUPPLY & DEMAND'!Q11 -> 46620 | M11: ='SUPPLY & DEMAND'!Q12 -> 99900 | O11: ='SUPPLY & DEMAND'!Q20 -> 57872.223 | Q11: ='SUPPLY & DEMAND'!Q13 -> 133200 | S11: ='SUPPLY & DEMAND'!Q14 -> 233100 | U11: ='SUPPLY & DEMAND'!Q15 -> 333000 | W11: ='SUPPLY & DEMAND'!Q16 -> 199800 | Y11: ='SUPPLY & DEMAND'!Q17 -> 499500 | AA11: ='SUPPLY & DEMAND'!Q19 -> 147311.11 | AC11: =SUM(AC6:AC10) -> 2416303.3
E12: =E11-E6 -> 0 | G12: =G11-G6 -> 36219.333 | I12: =I11-I7 -> 0 | K12: =K11-K7 -> 0 | M12: =M11-M7 -> 0 | O12: =O11-O7 -> 0 | Q12: =Q11-Q7 -> 0 | S12: =S11-S7 -> 0 | U12: =U11-U7 -> 119910.22 | W12: =W11-W8 -> 0 | Y12: =Y11-Y8 -> 456764.72 | AA12: =AA11-AA10 -> 0
G13: =G12-G7 -> 0 | U13: =U12-U8 -> 0 | Y13: =Y12-Y9 -> 94319.22
Y14: =Y13-Y10 -> 0
D15: TOTAL AVOCADO TRANSPORTATION COST | F15: =(E6/F6)+(G6/H6)+(G7/H7)+(I7/J7)+(K7/L7)+(M7/N7)+(O7/P7)+(Q7/R7)+(S7/T7)+(U7/V7)+(U8/V8)+(W8/X8)+(Y8/Z8)+(Y9/Z9)+(Y10/Z10)+(AA10/AB10) -> 187497.91
D19: NORTHWEST CORNER
D20: SCENARIO NO.2 MANGO
D21: Origen / Destino | E21: San Diego, CA | G21: Los Ángeles, CA | I21: San Francisco, CA | K21: Portland, OR | M21: Seattle, WA | O21: Vancouver, CAN | Q21: Phoenix, AZ | R21: Dallas, TX | S21: Dallas, TX | T21: Atlanta, GA | U21: Chicago, IL | V21: Atlanta, GA | W21: Atlanta, GA | X21: Dallas, TX | Y21: Nueva York, NY | Z21: Toronto, CAN | AA21: Toronto, CAN | AC21: SUPPLY
D22: Guadalajara, JA | E22: =E27 -> 46680 | F22: 15.555556 | G22: =G27 -> 280080 | H22: 14.705882 | I22: =AF22 -> 1562.5 | J22: 12.589928 | L22: 10.542169 | N22: 9.5890411 | P22: 9.0206186 | R22: 17.676768 | T22: 19.886364 | V22: 11.744966 | X22: 10.869565 | Z22: 8.6419753 | AB22: 9.8870056 | AC22: {='SUPPLY & DEMAND'!J16:K16} -> 328322.5 | AD22: 0 | AE22: =AC22-E22 -> 281642.5 | AF22: =AE22-G22 -> 1562.5 | AG22: =AF22-I22 -> 0
D23: Uruapan, MI | F23: 16.055046 | H23: 15.151515 | I23: =I28 -> 91797.5 | J23: 12.915129 | K23: =K27 -> 35010 | L23: 10.769231 | M23: =M27 -> 46680 | N23: 9.7765363 | O23: =O27 -> 62160 | P23: 9.1863517 | Q23: =Q27 -> 70020 | R23: 18.324607 | S23: =S27 -> 93360 | T23: 20.710059 | U23: =AJ23 -> 60624 | V23: 12.027491 | X23: 11.111111 | Z23: 8.7939698 | AB23: 10.086455 | AC23: {='SUPPLY & DEMAND'!J17:K17} -> 459651.5 | AD23: 0 | AE23: =AC23-I23 -> 367854 | AF23: =AE23-K23 -> 332844 | AG23: =AF23-M23 -> 286164 | AH23: =AG23-O23 -> 224004 | AI23: =AH23-Q23 -> 153984 | AJ23: =AI23-S23 -> 60624 | AK23: =AJ23-U23 -> 0
D24: Monterrey, NL | F24: 21.212121 | H24: 19.662921 | J24: 16.055046 | L24: 12.867647 | N24: 11.47541 | P24: 10.670732 | R24: 25.362319 | T24: 30.172414 | U24: =U28 -> 102756 | V24: 14.705882 | W24: =W27 -> 70020 | X24: 13.358779 | Y24: =AF24 -> 24217.5 | Z24: 10.144928 | AB24: 11.904762 | AC24: {='SUPPLY & DEMAND'!J18:K18} -> 196993.5 | AD24: 0 | AE24: =AC24-U24 -> 94237.5 | AF24: =AE24-W24 -> 24217.5 | AG24: =AF24-Y24 -> 0
D25: Hermosillo, SN | F25: 41.176471 | H25: 35.714286 | J25: 25.362319 | L25: 18.229167 | N25: 15.555556 | P25: 14.112903 | R25: 60.344828 | T25: 24.137931 | V25: 13.108614 | X25: 12.027491 | Y25: =AC25 -> 196993.5 | Z25: 9.3582888 | AB25: 10.835913 | AC25: {='SUPPLY & DEMAND'!J19:K19} -> 196993.5 | AD25: 0 | AE25: =AC25-Y25 -> 0
D26: Laredo, TX | F26: 22.580645 | H26: 20.833333 | J26: 16.826923 | L26: 13.358779 | N26: 11.864407 | P26: 11.006289 | R26: 27.34375 | T26: 54.6875 | V26: 18.817204 | X26: 16.666667 | Y26: =Y29 -> 12189 | Z26: 11.945392 | AA26: =AE26 -> 119140 | AB26: 14.46281 | AC26: {='SUPPLY & DEMAND'!J20:K20} -> 131329 | AD26: 0 | AE26: =AC26-Y26 -> 119140 | AF26: =AE26-AA26 -> 0
D27: DEMAND | E27: ='SUPPLY & DEMAND'!Q27 -> 46680 | G27: ='SUPPLY & DEMAND'!Q28 -> 280080 | I27: ='SUPPLY & DEMAND'!Q29 -> 93360 | K27: ='SUPPLY & DEMAND'!Q30 -> 35010 | M27: ='SUPPLY & DEMAND'!Q31 -> 46680 | O27: ='SUPPLY & DEMAND'!Q39 -> 62160 | Q27: ='SUPPLY & DEMAND'!Q32 -> 70020 | S27: ='SUPPLY & DEMAND'!Q33 -> 93360 | U27: ='SUPPLY & DEMAND'!Q34 -> 163380 | W27: ='SUPPLY & DEMAND'!Q35 -> 70020 | Y27: ='SUPPLY & DEMAND'!Q36 -> 233400 | AA27: ='SUPPLY & DEMAND'!Q38 -> 119140 | AC27: =SUM(AC22:AC26) -> 1313290
E28: =E27-E22 -> 0 | G28: =G27-G22 -> 0 | I28: =I27-I22 -> 91797.5 | K28: =K27-K23 -> 0 | M28: =M27-M23 -> 0 | O28: =O27-O23 -> 0 | Q28: =Q27-Q23 -> 0 | S28: =S27-S23 -> 0 | U28: =U27-U23 -> 102756 | W28: =W27-W24 -> 0 | Y28: =Y27-Y24 -> 209182.5 | AA28: =AA27-AA26 -> 0
I29: =I28-I23 -> 0 | U29: =U28-U24 -> 0 | Y29: =Y28-Y25 -> 12189
Y30: =Y29-Y26 -> 0
D32: TOTAL MANGOES TRANSPORTATION COST | F32: =(E22/F22)+(G22/H22)+(I22/J22)+(I23/J23)+(K23/L23)+(M23/N23)+(O23/P23)+(Q23/R23)+(S23/T23)+(U23/V23)+(U24/V24)+(W24/X24)+(Y24/Z24)+(Y25/Z25)+(Y26/Z26)+(AA26/AB26) -> 102364.13
D38: NORTHWEST CORNER
D39: SCENARIO NO.3 SALAD
D40: Origen / Destino | E40: San Diego, CA | G40: Los Ángeles, CA | I40: San Francisco, CA | K40: Portland, OR | M40: Seattle, WA | O40: Vancouver, CAN | Q40: Phoenix, AZ | R40: Dallas, TX | S40: Dallas, TX | T40: Atlanta, GA | U40: Chicago, IL | V40: Atlanta, GA | W40: Atlanta, GA | X40: Dallas, TX | Y40: Nueva York, NY | Z40: Toronto, CAN | AA40: Toronto, CAN | AC40: SUPPLY
D41: Guadalajara, JA | E41: =E46 -> 166800 | F41: ='TRANSPORTATION COST '!F61 -> 14.222222 | G41: =AE41 -> 470784 | H41: ='TRANSPORTATION COST '!G61 -> 13.445378 | J41: ='TRANSPORTATION COST '!H61 -> 11.510791 | L41: ='TRANSPORTATION COST '!I61 -> 9.6385542 | N41: ='TRANSPORTATION COST '!J61 -> 8.7671233 | P41: ='TRANSPORTATION COST '!K61 -> 8.2474227 | R41: ='TRANSPORTATION COST '!F68 -> 16.161616 | T41: ='TRANSPORTATION COST '!G68 -> 18.181818 | V41: ='TRANSPORTATION COST '!H68 -> 10.738255 | X41: ='TRANSPORTATION COST '!I68 -> 9.9378882 | Z41: ='TRANSPORTATION COST '!J68 -> 7.9012346 | AB41: ='TRANSPORTATION COST '!K68 -> 9.039548 | AC41: {='SUPPLY & DEMAND'!J24:K24} -> 637584 | AD41: 0 | AE41: =AC41-E41 -> 470784 | AF41: =AE41-G41 -> 0
D42: Uruapan, MI | F42: ='TRANSPORTATION COST '!F62 -> 14.678899 | G42: =G47 -> 113016 | H42: ='TRANSPORTATION COST '!G62 -> 13.852814 | I42: =I46 -> 250200 | J42: ='TRANSPORTATION COST '!H62 -> 11.808118 | K42: =K46 -> 125100 | L42: ='TRANSPORTATION COST '!I62 -> 9.8461538 | M42: =M46 -> 166800 | N42: ='TRANSPORTATION COST '!J62 -> 8.9385475 | O42: =O46 -> 117600 | P42: ='TRANSPORTATION COST '!K62 -> 8.3989501 | Q42: =Q46 -> 150120 | R42: ='TRANSPORTATION COST '!F69 -> 16.753927 | S42: =S46 -> 208500 | T42: ='TRANSPORTATION COST '!G69 -> 18.934911 | U42: =AK42 -> 143832 | V42: ='TRANSPORTATION COST '!H69 -> 10.996564 | X42: ='TRANSPORTATION COST '!I69 -> 10.15873 | Z42: ='TRANSPORTATION COST '!J69 -> 8.040201 | AB42: ='TRANSPORTATION COST '!K69 -> 9.221902 | AC42: {='SUPPLY & DEMAND'!J25:K25} -> 1275168 | AD42: 0 | AE42: =AC42-G42 -> 1162152 | AF42: =AE42-I42 -> 911952 | AG42: =AF42-K42 -> 786852 | AH42: =AG42-M42 -> 620052 | AI42: =AH42-O42 -> 502452 | AJ42: =AI42-Q42 -> 352332 | AK42: =AJ42-S42 -> 143832 | AL42: =AK42-U42 -> 0
D43: Monterrey, NL | F43: ='TRANSPORTATION COST '!F63 -> 19.393939 | H43: ='TRANSPORTATION COST '!G63 -> 17.977528 | J43: ='TRANSPORTATION COST '!H63 -> 14.678899 | L43: ='TRANSPORTATION COST '!I63 -> 11.764706 | N43: ='TRANSPORTATION COST '!J63 -> 10.491803 | P43: ='TRANSPORTATION COST '!K63 -> 9.7560976 | R43: ='TRANSPORTATION COST '!F70 -> 23.188406 | T43: ='TRANSPORTATION COST '!G70 -> 27.586207 | U43: =U47 -> 273168 | V43: ='TRANSPORTATION COST '!H70 -> 13.445378 | W43: =W46 -> 166800 | X43: ='TRANSPORTATION COST '!I70 -> 12.21374 | Y43: =AF43 -> 38220 | Z43: ='TRANSPORTATION COST '!J70 -> 9.2753623 | AB43: ='TRANSPORTATION COST '!K70 -> 10.884354 | AC43: {='SUPPLY & DEMAND'!J26:K26} -> 478188 | AD43: 0 | AE43: =AC43-U43 -> 205020 | AF43: =AE43-W43 -> 38220 | AG43: =AF43-Y43 -> 0
D44: Hermosillo, SN | F44: ='TRANSPORTATION COST '!F64 -> 37.647059 | H44: ='TRANSPORTATION COST '!G64 -> 32.653061 | J44: ='TRANSPORTATION COST '!H64 -> 23.188406 | L44: ='TRANSPORTATION COST '!I64 -> 16.666667 | N44: ='TRANSPORTATION COST '!J64 -> 14.222222 | P44: ='TRANSPORTATION COST '!K64 -> 12.903226 | R44: ='TRANSPORTATION COST '!F71 -> 55.172414 | T44: ='TRANSPORTATION COST '!G71 -> 22.068966 | V44: ='TRANSPORTATION COST '!H71 -> 11.985019 | X44: ='TRANSPORTATION COST '!I71 -> 10.996564 | Y44: =AC44 -> 478188 | Z44: ='TRANSPORTATION COST '!J71 -> 8.5561497 | AB44: ='TRANSPORTATION COST '!K71 -> 9.9071207 | AC44: {='SUPPLY & DEMAND'!J27:K27} -> 478188 | AD44: 0 | AE44: =AC44-Y44 -> 0
D45: Laredo, TX | F45: ='TRANSPORTATION COST '!F65 -> 20.645161 | H45: ='TRANSPORTATION COST '!G65 -> 19.047619 | J45: ='TRANSPORTATION COST '!H65 -> 15.384615 | L45: ='TRANSPORTATION COST '!I65 -> 12.21374 | N45: ='TRANSPORTATION COST '!J65 -> 10.847458 | P45: ='TRANSPORTATION COST '!K65 -> 10.062893 | R45: ='TRANSPORTATION COST '!F72 -> 25 | T45: ='TRANSPORTATION COST '!G72 -> 50 | V45: ='TRANSPORTATION COST '!H72 -> 17.204301 | X45: ='TRANSPORTATION COST '!I72 -> 15.238095 | Y45: =Y48 -> 150792 | Z45: ='TRANSPORTATION COST '!J72 -> 10.921502 | AA45: =AE45 -> 168000 | AB45: ='TRANSPORTATION COST '!K72 -> 13.22314 | AC45: {='SUPPLY & DEMAND'!J28:K28} -> 318792 | AD45: 0 | AE45: =AC45-Y45 -> 168000 | AF45: =AE45-AA45 -> 0
D46: DEMAND | E46: ='SUPPLY & DEMAND'!Q45 -> 166800 | G46: ='SUPPLY & DEMAND'!Q46 -> 583800 | I46: ='SUPPLY & DEMAND'!Q47 -> 250200 | K46: ='SUPPLY & DEMAND'!Q48 -> 125100 | M46: ='SUPPLY & DEMAND'!Q49 -> 166800 | O46: ='SUPPLY & DEMAND'!Q57 -> 117600 | Q46: ='SUPPLY & DEMAND'!Q50 -> 150120 | S46: ='SUPPLY & DEMAND'!Q51 -> 208500 | U46: ='SUPPLY & DEMAND'!Q52 -> 417000 | W46: ='SUPPLY & DEMAND'!Q53 -> 166800 | Y46: ='SUPPLY & DEMAND'!Q54 -> 667200 | AA46: ='SUPPLY & DEMAND'!Q56 -> 168000 | AC46: =SUM(AC41:AC45) -> 3187920
E47: =E46-E41 -> 0 | G47: =G46-G41 -> 113016 | I47: =I46-I42 -> 0 | K47: =K46-K42 -> 0 | M47: =M46-M42 -> 0 | O47: =O46-O42 -> 0 | Q47: =Q46-Q42 -> 0 | S47: =S46-S42 -> 0 | U47: =U46-U42 -> 273168 | W47: =W46-W43 -> 0 | Y47: =Y46-Y43 -> 628980 | AA47: =AA46-AA45 -> 0
G48: =G47-G42 -> 0 | U48: =U47-U43 -> 0 | Y48: =Y47-Y44 -> 150792
Y49: =Y48-Y45 -> 0
D50: TOTAL SALAD TRANSPORTATION COST | F50: =(E41/F41)+(G41/H41)+(G42/H42)+(I42/J42)+(K42/L42)+(M42/N42)+(O42/P42)+(Q42/R42)+(S42/T42)+(U42/V42)+(U43/V43)+(W43/X43)+(Y43/Z43)+(Y44/Z44)+(Y45/Z45)+(AA45/AB45) -> 275003.55
